<xacro:macro name="inertial">
  <inertial>
    <mass value="1"/>
    <inertia ixx="100" ixy="0" ixz="0" iyy="100" iyz="0" izz="100" />
    <origin/>
  </inertial>
</xacro:macro>

<xacro:macro name="collision_cylinder" params="xyz rpy radius length">
  <collision>
    <origin xyz="${xyz}" rpy="{rpy}" />
    <geometry>
      <cylinder radius="${radius}" length="${length}" />
    </geometry>
    <contact_coefficients mu="0" kp="1000.0" kd="1.0"/>
  </collision>
</xacro:macro>

<xacro:macro name="joint" params="name origin child">
  <joint name="${name}" type="continuous">
    <origin xyz="${origin}" />
    <axis xyz="1 0 0" />
    <parent link="chassis"/>
    <child link="${child}"/>
  </joint>
</xacro:macro>

<robot name="testbot">

<link name="axis">

  <xacro:inertial />

  <visual>
    <origin xyz="0 0 0" rpy="1.57 0 0" />
    <geometry>
      <cylinder radius="0.01" length=".5" />
    </geometry>
    <material name="gray">
      <color rgba=".2 .2 .2 1" />
    </material>
  </visual>

  <xacro:collision_cylinder xyz="0 0 0" rpy="1.57 0 0" radius=".01" length=".5"/>

</link>

<link name="chassis">
  
  <xacro:inertial />

  <visual>
    <origin/>
    <geometry>
      <box size=".4 .8 .2" />
    </geometry>
    <material name="white">
      <color rgba="1 1 1 1"/>
    </material>
  </visual>

  <collision>
    <origin xyz="0 0 -.3" />
    <geometry>
      <box size=".4 .8 .2" />
    </geometry>
    <contact_coefficients mu="0" kp="1000.0" kd="1.0"/>
  </collision>
</link>

<joint name="connect" type="fixed">
  <origin xyz="0 0 0" />
  <parent link="axis"/>
  <child link="chassis"/>
</joint>

<link name="turret">
  
  <xacro:inertial />

  <visual>
    <origin xyz="0 0 0" />
    <geometry>
      <sphere radius=".2" />
    </geometry>
    <material name="white">
      <color rgba="1 1 1 1"/>
    </material>
  </visual>

  <collision>
    <origin xyz="0 0 0" />
    <geometry>
      <sphere radius=".2" />
    </geometry>
    <contact_coefficients mu="0" kp="1000.0" kd="1.0"/>
  </collision>
</link>

<link name="w1">
  
  <xacro:inertial />

  <visual>
    <origin xyz="0 0 0" rpy="0 1.57 0" />
    <geometry>
      <cylinder radius=".08" length=".06"/>
    </geometry>
    <material name="gray" />
  </visual>

  <xacro:collision_cylinder xyz="0 0 0" rpy="0 1.57 0" radius=".08" length=".06"/>

</link>

<link name="w2">

  <xacro:inertial />

  <visual>
    <origin xyz="0 0 0" rpy="0 1.57 0" />
    <geometry>
      <cylinder radius=".08" length=".06"/>
    </geometry>
    <material name="gray" />
  </visual>

  <xacro:collision_cylinder xyz="0 0 0" rpy="0 1.57 0" radius=".08" length=".06"/>

</link>

<link name="w3">
  
  <xacro:inertial />

  <visual>
    <origin xyz="0 0 0" rpy="0 1.57 0" />
    <geometry>
      <cylinder radius=".08" length=".06"/>
    </geometry>
    <material name="gray" />
  </visual>

  <xacro:collision_cylinder xyz="0 0 0" rpy="0 1.57 0" radius=".08" length=".06"/>

</link>

<link name="w4">
  
  <xacro:inertial />

  <visual>
    <origin xyz="0 0 0" rpy="0 1.57 0" />
    <geometry>
      <cylinder radius=".08" length=".06"/>
    </geometry>
    <material name="gray" />
  </visual>

  <xacro:collision_cylinder xyz="0 0 0" rpy="0 1.57 0" radius=".08" length=".06"/>

</link>

<link name="w5">
  
  <xacro:inertial />

  <visual>
    <origin xyz="0 0 0" rpy="0 1.57 0" />
    <geometry>
      <cylinder radius=".08" length=".06"/>
    </geometry>
    <material name="gray" />
  </visual>

  <xacro:collision_cylinder xyz="0 0 0" rpy="0 1.57 0" radius=".08" length=".06"/>

</link>

<link name="w6">
  
  <xacro:inertial />

  <visual>
    <origin xyz="0 0 0" rpy="0 1.57 0" />
    <geometry>
      <cylinder radius=".08" length=".06"/>
    </geometry>
    <material name="gray" />
  </visual>

  <xacro:collision_cylinder xyz="0 0 0" rpy="0 1.57 0" radius=".08" length=".06"/>

</link>

<link name="gun">
  
  <xacro:inertial />

  <visual>
    <origin xyz="0 0.25 0" rpy="1.57 0 0"/>
    <geometry>
      <cylinder radius=".05" length=".5" />
    </geometry>
    <material name="white" />
  </visual>

  <xacro:collision_cylinder xyz="0 .25 0" rpy="1.57 0 0" radius=".05" length=".5"/>

</link>

<joint name="ring" type="revolute">
  <origin xyz="0 0 0.1" />
  <parent link="chassis"/>
  <child link="turret"/>
  <axis xyz="0 0 1" />
  <limit upper="1.57" lower="-1.57" effort="10" velocity="10" />
</joint>

<xacro:joint name="j1" origin="-.2 .2 -.05" child="w1"/>
<xacro:joint name="j2" origin="-.2 0 -.05" child="w2"/>
<xacro:joint name="j3" origin="-.2 -.2 -.05" child="w3"/>
<xacro:joint name="j4" origin=".2 .2 -.05" child="w4"/>
<xacro:joint name="j5" origin=".2 0 -.05" child="w5"/>
<xacro:joint name="j6" origin=".2 -.2 -.05" child="w6"/>

<joint name="gunbase" type="revolute">
  <parent link="turret"/>
  <child link="gun"/>
  <origin xyz="0 0 0.1" rpy="0 0 0" />
  <axis xyz="1 0 0" />
  <limit upper="1.57" lower="-1.57" effort="10" velocity="10" />
</joint>

</robot>
